Workbook

Sheet Dashboard
A1: WeeklyAI · 收益预测仪表盘
A2: Base Case · 24个月预测 | 修改 Assumptions sheet 调整参数
A3: 关键里程碑指标 (Base Case)
A4: M6 MRR | C4: M12 MRR | E4: M24 MRR | G4: M6 订阅人数 | I4: M12 订阅人数
A5: ='Monthly Model'!G16 -> 126 | C5: ='Monthly Model'!M16 -> 689 | E5: ='Monthly Model'!Y16 -> 4228 | G5: ='Monthly Model'!G6 -> 465 | I5: ='Monthly Model'!M6 -> 824
A7: 投入成本摘要 (Cost Summary)
A8: 总开发工时 | B8: =Assumptions!B16 -> 305 | G8: hours
A9: 开发现金成本(时薪×工时) | B9: =Assumptions!B17 -> 30500 | G9: one-time
A10: 月度基础设施成本 | B10: =Assumptions!B28 -> 141 | G10: /月
A11: Year1 总基础设施 | B11: =Assumptions!B28*12 -> 1692 | G11: Year1
A12: 首年总现金投入 | B12: =Assumptions!B17+Assumptions!B28*12 -> 32192 | G12: Year1
A14: 盈亏平衡预测 (Break-even)
A15: 运营盈亏平衡 | B15: Month 7 | E15: 月度MRR覆盖基础设施成本
A16: 完全盈亏平衡 | B16: Month 14 | E16: 累计P&L转正（Base Case，含开发成本）
A17: Solo Founder完全盈亏 | B17: Month 8 | E17: 开发成本=$0，只看现金
A18: Year 2 ARR目标 | B18: $45,000-$60,000 | E18: Base Case年化收入
A20: 收入结构演变 (Revenue Mix Evolution)
A21: Month 1-3 | B21: 100% 免费 | F21: 无收入，积累订阅基础
A22: Month 4-6 | B22: Newsletter付费为主 | F22: 预计MRR $100-$300
A23: Month 7-12 | B23: Pro订阅开始贡献 | F23: 预计MRR $800-$2,500
A24: Month 13-24 | B24: Enterprise+数据报告加入 | F24: 预计MRR $3,500-$6,500+

Sheet Assumptions
A1: WeeklyAI — Financial Model Assumptions
A2: Blue = hardcoded input | Change to model your own scenario
A4: A 开发成本假设 (Development Cost)
A5: 参数 | B5: 数值 | C5: 说明 | D5: 单位
A6: 开发者时薪 | B6: 100 | C6: 自由职业市场价；solo founder可设为0看纯现金成本 | D6: $
A7: P0 修复工作量 | B7: 20 | C7: 博客过滤+语言修复+Hero CSS | D7: hours
A8: Email Digest 系统 | B8: 50 | C8: 前端订阅入口+Resend接入+Claude自动生成 | D8: hours
A9: 产品详情页升级 | B9: 30 | C9: 竞品模块+新闻时间线+pm_insight字段 | D9: hours
A10: 收藏夹情报板 | B10: 40 | C10: 标签/分组/导出/分享链接 | D10: hours
A11: 语义搜索 | B11: 50 | C11: Embedding生成+向量检索+混合排序 | D11: hours
A12: 横向对比功能 | B12: 35 | C12: 多产品并排对比+分享链接 | D12: hours
A13: Weekly汇总页 | B13: 20 | C13: /weekly路由+后端新接口 | D13: hours
A14: Discover个性化 | B14: 30 | C14: localStorage偏好学习+权重排序 | D14: hours
A15: Mobile体验优化 | B15: 30 | C15: 响应式修复+手势交互 | D15: hours
A16: → 总开发工时 | B16: =SUM(B7:B15) -> 305 | C16: 所有功能合计 | D16: hours
A17: → 总开发现金成本 | B17: =B6*B16 -> 30500 | C17: 时薪 × 工时（solo founder = $0） | D17: $
A19: B 每月基础设施成本 (Monthly Infrastructure)
A20: 参数 | B20: 数值 | C20: 说明 | D20: 单位
A21: Vercel Pro (前端托管) | B21: 20 | C21: 免费额度够用前可用Hobby($0)，流量大后升级 | D21: $
A22: MongoDB Atlas M10 | B22: 57 | C22: 当前规模M2($9)够用，增长后升级 | D22: $
A23: Perplexity API | B23: 28 | C23: Sonar Pro ~$35/月，base sonar ~$20/月，取中间值 | D23: $
A24: Zhipu GLM API (中国区) | B24: 7 | C24: ¥50/月 ≈ $7，search_pro模式 | D24: $
A25: Claude API (Digest生成) | B25: 8 | C25: 每周1次，~500tokens × 52周 ÷ 12 ≈ 微小成本 | D25: $
A26: Resend (邮件发送) | B26: 20 | C26: ≤3000封/月免费；>3000封后$20/月起 | D26: $
A27: 域名/SSL | B27: 1 | C27: ~$15/年分摊 | D27: $
A28: → 每月基础设施合计 | B28: =SUM(B21:B27) -> 141 | C28: 不含人力成本的月度运营成本 | D28: $/月
A30: C 收入假设 (Revenue Assumptions)
A31: 参数 | B31: 数值 | C31: 说明 | D31: 单位
A32: ── 免费邮件订阅增长率 (M1-6) | B32: 0.15 | C32: 每月新增订阅用户百分比 | D32: %
A33: ── 免费邮件订阅增长率 (M7-12) | B33: 0.1 | C33: 增速自然放缓 | D33: %
A34: ── 免费邮件订阅增长率 (M13-24) | B34: 0.07 | C34: 成熟期稳定增速 | D34: %
A35: ── 初始免费订阅基数 (M0) | B35: 200 | C35: 上线时通过现有用户转化的估算 | D35: 人
A36: ── 付费Newsletter转化率 | B36: 0.03 | C36: 行业B2B niche订阅3-5%属正常 | D36: %
A37: ── 付费Newsletter价格 | B37: 9 | C37: $9/月 或 $89/年（选月付） | D37: $
A38: ── Newsletter付费启动月份 | B38: 4 | C38: 第4个月推出付费层 | D38: Month
A39: ── 竞品情报Pro转化率(占MAU) | B39: 0.006 | C39: 参考Linear/Notion早期B2B转化 | D39: %
A40: ── 竞品情报Pro定价 | B40: 29 | C40: $29/月/用户，偏低定价打开市场 | D40: $
A41: ── 竞品情报启动月份 | B41: 7 | C41: 第7个月推出Pro订阅 | D41: Month
A42: ── Enterprise客户数(Year2起) | B42: 8 | C42: 保守估算，依靠口碑/BD | D42: 个
A43: ── Enterprise月均定价 | B43: 199 | C43: $199/月/企业，可协商上调 | D43: $
...

Sheet Monthly Model
A1: WeeklyAI — 24个月收益预测模型（Base Case）
A2: 黑色=公式 蓝色=假设输入 | 修改Assumptions sheet调整参数
A4: 指标 | B4: M1 (Y1) | C4: M2 (Y1) | D4: M3 (Y1) | E4: M4 (Y1) | F4: M5 (Y1) | G4: M6 (Y1) | H4: M7 (Y1) | I4: M8 (Y1) | J4: M9 (Y1) | K4: M10 (Y1) | L4: M11 (Y1) | M4: M12 (Y1) | N4: M13 (Y2) | O4: M14 (Y2) | P4: M15 (Y2) | Q4: M16 (Y2) | R4: M17 (Y2) | S4: M18 (Y2) | T4: M19 (Y2) | U4: M20 (Y2) | V4: M21 (Y2) | W4: M22 (Y2) | X4: M23 (Y2) | Y4: M24 (Y2)
A5: 用户增长 (User Growth)
A6: 免费邮件订阅人数 | B6: =ROUND(Assumptions!B35*(1+Assumptions!B32),0) -> 230 | C6: =ROUND(B6*(1+Assumptions!B32),0) -> 265 | D6: =ROUND(C6*(1+Assumptions!B32),0) -> 305 | E6: =ROUND(D6*(1+Assumptions!B32),0) -> 351 | F6: =ROUND(E6*(1+Assumptions!B32),0) -> 404 | G6: =ROUND(F6*(1+Assumptions!B32),0) -> 465 | H6: =ROUND(G6*(1+Assumptions!B33),0) -> 512 | I6: =ROUND(H6*(1+Assumptions!B33),0) -> 563 | J6: =ROUND(I6*(1+Assumptions!B33),0) -> 619 | K6: =ROUND(J6*(1+Assumptions!B33),0) -> 681 | L6: =ROUND(K6*(1+Assumptions!B33),0) -> 749 | M6: =ROUND(L6*(1+Assumptions!B33),0) -> 824 | N6: =ROUND(M6*(1+Assumptions!B34),0) -> 882 | O6: =ROUND(N6*(1+Assumptions!B34),0) -> 944 | P6: =ROUND(O6*(1+Assumptions!B34),0) -> 1010 | Q6: =ROUND(P6*(1+Assumptions!B34),0) -> 1081 | R6: =ROUND(Q6*(1+Assumptions!B34),0) -> 1157 | S6: =ROUND(R6*(1+Assumptions!B34),0) -> 1238 | T6: =ROUND(S6*(1+Assumptions!B34),0) -> 1325 | U6: =ROUND(T6*(1+Assumptions!B34),0) -> 1418 | V6: =ROUND(U6*(1+Assumptions!B34),0) -> 1517 | W6: =ROUND(V6*(1+Assumptions!B34),0) -> 1623 | X6: =ROUND(W6*(1+Assumptions!B34),0) -> 1737 | Y6: =ROUND(X6*(1+Assumptions!B34),0) -> 1859
A7: 月活用户 MAU (估算) | B7: =ROUND(B6*3.94,0) -> 906 | C7: =ROUND(C6*3.88,0) -> 1028 | D7: =ROUND(D6*3.82,0) -> 1165 | E7: =ROUND(E6*3.76,0) -> 1320 | F7: =ROUND(F6*3.7,0) -> 1495 | G7: =ROUND(G6*3.64,0) -> 1693 | H7: =ROUND(H6*3.58,0) -> 1833 | I7: =ROUND(I6*3.52,0) -> 1982 | J7: =ROUND(J6*3.46,0) -> 2142 | K7: =ROUND(K6*3.4,0) -> 2315 | L7: =ROUND(L6*3.34,0) -> 2502 | M7: =ROUND(M6*3.28,0) -> 2703 | N7: =ROUND(N6*3.22,0) -> 2840 | O7: =ROUND(O6*3.16,0) -> 2983 | P7: =ROUND(P6*3.1,0) -> 3131 | Q7: =ROUND(Q6*3.04,0) -> 3286 | R7: =ROUND(R6*2.98,0) -> 3448 | S7: =ROUND(S6*2.92,0) -> 3615 | T7: =ROUND(T6*2.86,0) -> 3790 | U7: =ROUND(U6*2.8,0) -> 3970 | V7: =ROUND(V6*2.74,0) -> 4157 | W7: =ROUND(W6*2.68,0) -> 4350 | X7: =ROUND(X6*2.62,0) -> 4551 | Y7: =ROUND(Y6*2.56,0) -> 4759
A8: 付费Newsletter订阅人数 | B8: =IF(1>=Assumptions!B38,ROUND(B6*Assumptions!B36,0),0) -> 0 | C8: =IF(2>=Assumptions!B38,ROUND(C6*Assumptions!B36,0),0) -> 0 | D8: =IF(3>=Assumptions!B38,ROUND(D6*Assumptions!B36,0),0) -> 0 | E8: =IF(4>=Assumptions!B38,ROUND(E6*Assumptions!B36,0),0) -> 11 | F8: =IF(5>=Assumptions!B38,ROUND(F6*Assumptions!B36,0),0) -> 12 | G8: =IF(6>=Assumptions!B38,ROUND(G6*Assumptions!B36,0),0) -> 14 | H8: =IF(7>=Assumptions!B38,ROUND(H6*Assumptions!B36,0),0) -> 15 | I8: =IF(8>=Assumptions!B38,ROUND(I6*Assumptions!B36,0),0) -> 17 | J8: =IF(9>=Assumptions!B38,ROUND(J6*Assumptions!B36,0),0) -> 19 | K8: =IF(10>=Assumptions!B38,ROUND(K6*Assumptions!B36,0),0) -> 20 | L8: =IF(11>=Assumptions!B38,ROUND(L6*Assumptions!B36,0),0) -> 22 | M8: =IF(12>=Assumptions!B38,ROUND(M6*Assumptions!B36,0),0) -> 25 | N8: =IF(13>=Assumptions!B38,ROUND(N6*Assumptions!B36,0),0) -> 26 | O8: =IF(14>=Assumptions!B38,ROUND(O6*Assumptions!B36,0),0) -> 28 | P8: =IF(15>=Assumptions!B38,ROUND(P6*Assumptions!B36,0),0) -> 30 | Q8: =IF(16>=Assumptions!B38,ROUND(Q6*Assumptions!B36,0),0) -> 32 | R8: =IF(17>=Assumptions!B38,ROUND(R6*Assumptions!B36,0),0) -> 35 | S8: =IF(18>=Assumptions!B38,ROUND(S6*Assumptions!B36,0),0) -> 37 | T8: =IF(19>=Assumptions!B38,ROUND(T6*Assumptions!B36,0),0) -> 40 | U8: =IF(20>=Assumptions!B38,ROUND(U6*Assumptions!B36,0),0) -> 43 | V8: =IF(21>=Assumptions!B38,ROUND(V6*Assumptions!B36,0),0) -> 46 | W8: =IF(22>=Assumptions!B38,ROUND(W6*Assumptions!B36,0),0) -> 49 | X8: =IF(23>=Assumptions!B38,ROUND(X6*Assumptions!B36,0),0) -> 52 | Y8: =IF(24>=Assumptions!B38,ROUND(Y6*Assumptions!B36,0),0) -> 56
A9: 竞品情报 Pro 订阅人数 | B9: =IF(1>=Assumptions!B41,ROUND(B7*Assumptions!B39,0),0) -> 0 | C9: =IF(2>=Assumptions!B41,ROUND(C7*Assumptions!B39,0),0) -> 0 | D9: =IF(3>=Assumptions!B41,ROUND(D7*Assumptions!B39,0),0) -> 0 | E9: =IF(4>=Assumptions!B41,ROUND(E7*Assumptions!B39,0),0) -> 0 | F9: =IF(5>=Assumptions!B41,ROUND(F7*Assumptions!B39,0),0) -> 0 | G9: =IF(6>=Assumptions!B41,ROUND(G7*Assumptions!B39,0),0) -> 0 | H9: =IF(7>=Assumptions!B41,ROUND(H7*Assumptions!B39,0),0) -> 11 | I9: =IF(8>=Assumptions!B41,ROUND(I7*Assumptions!B39,0),0) -> 12 | J9: =IF(9>=Assumptions!B41,ROUND(J7*Assumptions!B39,0),0) -> 13 | K9: =IF(10>=Assumptions!B41,ROUND(K7*Assumptions!B39,0),0) -> 14 | L9: =IF(11>=Assumptions!B41,ROUND(L7*Assumptions!B39,0),0) -> 15 | M9: =IF(12>=Assumptions!B41,ROUND(M7*Assumptions!B39,0),0) -> 16 | N9: =IF(13>=Assumptions!B41,ROUND(N7*Assumptions!B39,0),0) -> 17 | O9: =IF(14>=Assumptions!B41,ROUND(O7*Assumptions!B39,0),0) -> 18 | P9: =IF(15>=Assumptions!B41,ROUND(P7*Assumptions!B39,0),0) -> 19 | Q9: =IF(16>=Assumptions!B41,ROUND(Q7*Assumptions!B39,0),0) -> 20 | R9: =IF(17>=Assumptions!B41,ROUND(R7*Assumptions!B39,0),0) -> 21 | S9: =IF(18>=Assumptions!B41,ROUND(S7*Assumptions!B39,0),0) -> 22 | T9: =IF(19>=Assumptions!B41,ROUND(T7*Assumptions!B39,0),0) -> 23 | U9: =IF(20>=Assumptions!B41,ROUND(U7*Assumptions!B39,0),0) -> 24 | V9: =IF(21>=Assumptions!B41,ROUND(V7*Assumptions!B39,0),0) -> 25 | W9: =IF(22>=Assumptions!B41,ROUND(W7*Assumptions!B39,0),0) -> 26 | X9: =IF(23>=Assumptions!B41,ROUND(X7*Assumptions!B39,0),0) -> 27 | Y9: =IF(24>=Assumptions!B41,ROUND(Y7*Assumptions!B39,0),0) -> 29
A10: Enterprise 客户数 | B10: 0 | C10: 0 | D10: 0 | E10: 0 | F10: 0 | G10: 0 | H10: 0 | I10: 0 | J10: 0 | K10: 0 | L10: 0 | M10: 0 | N10: =ROUND(Assumptions!B42*0.4,0) -> 3 | O10: =MIN(N10+1,Assumptions!B42) -> 4 | P10: =MIN(O10+1,Assumptions!B42) -> 5 | Q10: =MIN(P10+1,Assumptions!B42) -> 6 | R10: =MIN(Q10+1,Assumptions!B42) -> 7 | S10: =MIN(R10+1,Assumptions!B42) -> 8 | T10: =MIN(S10+1,Assumptions!B42+4) -> 9 | U10: =MIN(T10+1,Assumptions!B42+4) -> 10 | V10: =MIN(U10+1,Assumptions!B42+4) -> 11 | W10: =MIN(V10+1,Assumptions!B42+4) -> 12 | X10: =MIN(W10+1,Assumptions!B42+4) -> 12 | Y10: =MIN(X10+1,Assumptions!B42+4) -> 12
A11: 收入 Revenue ($)
A12: Newsletter 付费收入 | B12: =IF(1>=Assumptions!B38,B8*Assumptions!B37,0) -> 0 | C12: =IF(2>=Assumptions!B38,C8*Assumptions!B37,0) -> 0 | D12: =IF(3>=Assumptions!B38,D8*Assumptions!B37,0) -> 0 | E12: =IF(4>=Assumptions!B38,E8*Assumptions!B37,0) -> 99 | F12: =IF(5>=Assumptions!B38,F8*Assumptions!B37,0) -> 108 | G12: =IF(6>=Assumptions!B38,G8*Assumptions!B37,0) -> 126 | H12: =IF(7>=Assumptions!B38,H8*Assumptions!B37,0) -> 135 | I12: =IF(8>=Assumptions!B38,I8*Assumptions!B37,0) -> 153 | J12: =IF(9>=Assumptions!B38,J8*Assumptions!B37,0) -> 171 | K12: =IF(10>=Assumptions!B38,K8*Assumptions!B37,0) -> 180 | L12: =IF(11>=Assumptions!B38,L8*Assumptions!B37,0) -> 198 | M12: =IF(12>=Assumptions!B38,M8*Assumptions!B37,0) -> 225 | N12: =IF(13>=Assumptions!B38,N8*Assumptions!B37,0) -> 234 | O12: =IF(14>=Assumptions!B38,O8*Assumptions!B37,0) -> 252 | P12: =IF(15>=Assumptions!B38,P8*Assumptions!B37,0) -> 270 | Q12: =IF(16>=Assumptions!B38,Q8*Assumptions!B37,0) -> 288 | R12: =IF(17>=Assumptions!B38,R8*Assumptions!B37,0) -> 315 | S12: =IF(18>=Assumptions!B38,S8*Assumptions!B37,0) -> 333 | T12: =IF(19>=Assumptions!B38,T8*Assumptions!B37,0) -> 360 | U12: =IF(20>=Assumptions!B38,U8*Assumptions!B37,0) -> 387 | V12: =IF(21>=Assumptions!B38,V8*Assumptions!B37,0) -> 414 | W12: =IF(22>=Assumptions!B38,W8*Assumptions!B37,0) -> 441 | X12: =IF(23>=Assumptions!B38,X8*Assumptions!B37,0) -> 468 | Y12: =IF(24>=Assumptions!B38,Y8*Assumptions!B37,0) -> 504
A13: 竞品情报 Pro 收入 | B13: =IF(1>=Assumptions!B41,B9*Assumptions!B40,0) -> 0 | C13: =IF(2>=Assumptions!B41,C9*Assumptions!B40,0) -> 0 | D13: =IF(3>=Assumptions!B41,D9*Assumptions!B40,0) -> 0 | E13: =IF(4>=Assumptions!B41,E9*Assumptions!B40,0) -> 0 | F13: =IF(5>=Assumptions!B41,F9*Assumptions!B40,0) -> 0 | G13: =IF(6>=Assumptions!B41,G9*Assumptions!B40,0) -> 0 | H13: =IF(7>=Assumptions!B41,H9*Assumptions!B40,0) -> 319 | I13: =IF(8>=Assumptions!B41,I9*Assumptions!B40,0) -> 348 | J13: =IF(9>=Assumptions!B41,J9*Assumptions!B40,0) -> 377 | K13: =IF(10>=Assumptions!B41,K9*Assumptions!B40,0) -> 406 | L13: =IF(11>=Assumptions!B41,L9*Assumptions!B40,0) -> 435 | M13: =IF(12>=Assumptions!B41,M9*Assumptions!B40,0) -> 464 | N13: =IF(13>=Assumptions!B41,N9*Assumptions!B40,0) -> 493 | O13: =IF(14>=Assumptions!B41,O9*Assumptions!B40,0) -> 522 | P13: =IF(15>=Assumptions!B41,P9*Assumptions!B40,0) -> 551 | Q13: =IF(16>=Assumptions!B41,Q9*Assumptions!B40,0) -> 580 | R13: =IF(17>=Assumptions!B41,R9*Assumptions!B40,0) -> 609 | S13: =IF(18>=Assumptions!B41,S9*Assumptions!B40,0) -> 638 | T13: =IF(19>=Assumptions!B41,T9*Assumptions!B40,0) -> 667 | U13: =IF(20>=Assumptions!B41,U9*Assumptions!B40,0) -> 696 | V13: =IF(21>=Assumptions!B41,V9*Assumptions!B40,0) -> 725 | W13: =IF(22>=Assumptions!B41,W9*Assumptions!B40,0) -> 754 | X13: =IF(23>=Assumptions!B41,X9*Assumptions!B40,0) -> 783 | Y13: =IF(24>=Assumptions!B41,Y9*Assumptions!B40,0) -> 841
A14: Enterprise 订阅收入 | B14: =IF(1>=Assumptions!B44,B10*Assumptions!B43,0) -> 0 | C14: =IF(2>=Assumptions!B44,C10*Assumptions!B43,0) -> 0 | D14: =IF(3>=Assumptions!B44,D10*Assumptions!B43,0) -> 0 | E14: =IF(4>=Assumptions!B44,E10*Assumptions!B43,0) -> 0 | F14: =IF(5>=Assumptions!B44,F10*Assumptions!B43,0) -> 0 | G14: =IF(6>=Assumptions!B44,G10*Assumptions!B43,0) -> 0 | H14: =IF(7>=Assumptions!B44,H10*Assumptions!B43,0) -> 0 | I14: =IF(8>=Assumptions!B44,I10*Assumptions!B43,0) -> 0 | J14: =IF(9>=Assumptions!B44,J10*Assumptions!B43,0) -> 0 | K14: =IF(10>=Assumptions!B44,K10*Assumptions!B43,0) -> 0 | L14: =IF(11>=Assumptions!B44,L10*Assumptions!B43,0) -> 0 | M14: =IF(12>=Assumptions!B44,M10*Assumptions!B43,0) -> 0 | N14: =IF(13>=Assumptions!B44,N10*Assumptions!B43,0) -> 597 | O14: =IF(14>=Assumptions!B44,O10*Assumptions!B43,0) -> 796 | P14: =IF(15>=Assumptions!B44,P10*Assumptions!B43,0) -> 995 | Q14: =IF(16>=Assumptions!B44,Q10*Assumptions!B43,0) -> 1194 | R14: =IF(17>=Assumptions!B44,R10*Assumptions!B43,0) -> 1393 | S14: =IF(18>=Assumptions!B44,S10*Assumptions!B43,0) -> 1592 | T14: =IF(19>=Assumptions!B44,T10*Assumptions!B43,0) -> 1791 | U14: =IF(20>=Assumptions!B44,U10*Assumptions!B43,0) -> 1990 | V14: =IF(21>=Assumptions!B44,V10*Assumptions!B43,0) -> 2189 | W14: =IF(22>=Assumptions!B44,W10*Assumptions!B43,0) -> 2388 | X14: =IF(23>=Assumptions!B44,X10*Assumptions!B43,0) -> 2388 | Y14: =IF(24>=Assumptions!B44,Y10*Assumptions!B43,0) -> 2388
A15: 数据报告收入 | B15: 0 | C15: 0 | D15: 0 | E15: 0 | F15: 0 | G15: 0 | H15: 0 | I15: 0 | J15: 0 | K15: 0 | L15: 0 | M15: 0 | N15: 0 | O15: 0 | P15: =Assumptions!B45*(Assumptions!B46/4) -> 495 | Q15: 0 | R15: 0 | S15: =Assumptions!B45*(Assumptions!B46/4) -> 495 | T15: 0 | U15: 0 | V15: =Assumptions!B45*(Assumptions!B46/4) -> 495 | W15: 0 | X15: 0 | Y15: =Assumptions!B45*(Assumptions!B46/4) -> 495
A16: 总月度收入 Total Revenue | B16: =SUM(B12:B15) -> 0 | C16: =SUM(C12:C15) -> 0 | D16: =SUM(D12:D15) -> 0 | E16: =SUM(E12:E15) -> 99 | F16: =SUM(F12:F15) -> 108 | G16: =SUM(G12:G15) -> 126 | H16: =SUM(H12:H15) -> 454 | I16: =SUM(I12:I15) -> 501 | ... Y16: =SUM(Y12:Y15) -> 4228
A17: 成本 Costs ($)
A18: 月度基础设施成本 | B18: =Assumptions!B28*1 -> 141 | C18: =Assumptions!B28*1.01 -> 142.41 | D18: =Assumptions!B28*1.02 -> 143.82 | E18: =Assumptions!B28*1.03 -> 145.23 | F18: =Assumptions!B28*1.04 -> 146.64 | G18: =Assumptions!B28*1.05 -> 148.05 | H18: =Assumptions!B28*1.06 -> 149.46 | I18: =Assumptions!B28*1.07 -> 150.87 | J18: =Assumptions!B28*1.08 -> 152.28 | K18: =Assumptions!B28*1.09 -> 153.69 | L18: =Assumptions!B28*1.1 -> 155.1 | M18: =Assumptions!B28*1.11 -> 156.51 | N18: =Assumptions!B28*1.12 -> 157.92 | O18: =Assumptions!B28*1.13 -> 159.33 | P18: =Assumptions!B28*1.14 -> 160.74 | Q18: =Assumptions!B28*1.15 -> 162.15 | R18: =Assumptions!B28*1.16 -> 163.56 | S18: =Assumptions!B28*1.17 -> 164.97 | T18: =Assumptions!B28*1.18 -> 166.38 | U18: =Assumptions!B28*1.19 -> 167.79 | V18: =Assumptions!B28*1.2 -> 169.2 | W18: =Assumptions!B28*1.21 -> 170.61 | X18: =Assumptions!B28*1.22 -> 172.02 | Y18: =Assumptions!B28*1.23 -> 173.43
A19: Claude API增量成本(Digest) | B19: =ROUND(B6*0.003,1) -> 0.7 | C19: =ROUND(C6*0.003,1) -> 0.8 | D19: =ROUND(D6*0.003,1) -> 0.9 | E19: =ROUND(E6*0.003,1) -> 1.1 | F19: =ROUND(F6*0.003,1) -> 1.2 | G19: =ROUND(G6*0.003,1) -> 1.4 | H19: =ROUND(H6*0.003,1) -> 1.5 | I19: =ROUND(I6*0.003,1) -> 1.7 | ... Y19: =ROUND(Y6*0.003,1) -> 5.6
A20: 总月度成本 Total Cost | B20: =SUM(B18:B19) -> 141.7 | C20: =SUM(C18:C19) -> 143.21 | D20: =SUM(D18:D19) -> 144.72 | E20: =SUM(E18:E19) -> 146.33 | F20: =SUM(F18:F19) -> 147.84 | G20: =SUM(G18:G19) -> 149.45 | H20: =SUM(H18:H19) -> 150.96 | I20: =SUM(I18:I19) -> 152.57 | ... Y20: =SUM(Y18:Y19) -> 179.03
A21: 损益 P&L ($)
A22: 月度净利润 Monthly P&L | B22: =B16-B20 -> -141.7 | C22: =C16-C20 -> -143.21 | D22: =D16-D20 -> -144.72 | E22: =E16-E20 -> -47.33 | F22: =F16-F20 -> -39.84 | G22: =G16-G20 -> -23.45 | H22: =H16-H20 -> 303.04 | I22: =I16-I20 -> 348.43 | ... Y22: =Y16-Y20 -> 4048.97
A23: 累计P&L (含开发成本) | B23: =B22-Assumptions!B17 -> -30641.7 | C23: =B23+C22 -> -30784.91 | D23: =C23+D22 -> -30929.63 | E23: =D23+E22 -> -30976.96 | F23: =E23+F22 -> -31016.8 | G23: =F23+G22 -> -31040.25 | H23: =G23+H22 -> -30737.21 | I23: =H23+I22 -> -30388.78 | J23: =I23+J22 -> -29994.96 | ... Y23: =X23+Y22 -> 3211.54
A24: MRR 环比增长率 | B24: - | C24: =IFERROR(IF(B16=0,0,(C16-B16)/B16),0) -> 0 | D24: =IFERROR(IF(C16=0,0,(D16-C16)/C16),0) -> 0 | E24: =IFERROR(IF(D16=0,0,(E16-D16)/D16),0) -> 0 | F24: =IFERROR(IF(E16=0,0,(F16-E16)/E16),0) -> 0.090909091 | G24: =IFERROR(IF(F16=0,0,(G16-F16)/F16),0) -> 0.16666667 | H24: =IFERROR(IF(G16=0,0,(H16-G16)/G16),0) -> 2.6031746 | I24: =IFERROR(IF(H16=0,0,(I16-H16)/H16),0) -> 0.10352423 | J24: =IFERROR(IF(I16=0,0,(J16-I16)/I16),0) -> 0.093812375 | ... Y24: =IFERROR(IF(X16=0,0,(Y16-X16)/X16),0) -> 0.16185765

Sheet Scenario Comparison
A1: WeeklyAI — 三种情景对比 (Conservative / Base / Optimistic)
A2: 所有数值单位 $USD，Base Case与Monthly Model联动
A4: 指标 | B4: 悲观-M6 | C4: 悲观-M12 | D4: 悲观-M24 | E4: Base-M6 | F4: Base-M12 | G4: Base-M24 | H4: 乐观-M6 | I4: 乐观-M12 | J4: 乐观-M24
A5: 免费订阅人数 | B5: =ROUND('Monthly Model'!G6*0.55,0) -> 256 | C5: =ROUND('Monthly Model'!M6*0.55,0) -> 453 | D5: =ROUND('Monthly Model'!Y6*0.55,0) -> 1022 | E5: ='Monthly Model'!G6 -> 465 | F5: ='Monthly Model'!M6 -> 824 | G5: ='Monthly Model'!Y6 -> 1859 | H5: =ROUND('Monthly Model'!G6*1.8,0) -> 837 | I5: =ROUND('Monthly Model'!M6*1.8,0) -> 1483 | J5: =ROUND('Monthly Model'!Y6*1.8,0) -> 3346
A6: MAU | B6: =ROUND('Monthly Model'!G7*0.55,0) -> 931 | C6: =ROUND('Monthly Model'!M7*0.55,0) -> 1487 | D6: =ROUND('Monthly Model'!Y7*0.55,0) -> 2617 | E6: ='Monthly Model'!G7 -> 1693 | F6: ='Monthly Model'!M7 -> 2703 | G6: ='Monthly Model'!Y7 -> 4759 | H6: =ROUND('Monthly Model'!G7*1.8,0) -> 3047 | I6: =ROUND('Monthly Model'!M7*1.8,0) -> 4865 | J6: =ROUND('Monthly Model'!Y7*1.8,0) -> 8566
A7: 付费Newsletter订阅人数 | B7: =ROUND('Monthly Model'!G8*0.33,0) -> 5 | C7: =ROUND('Monthly Model'!M8*0.33,0) -> 8 | D7: =ROUND('Monthly Model'!Y8*0.33,0) -> 18 | E7: ='Monthly Model'!G8 -> 14 | F7: ='Monthly Model'!M8 -> 25 | G7: ='Monthly Model'!Y8 -> 56 | H7: =ROUND('Monthly Model'!G8*2.88,0) -> 40 | I7: =ROUND('Monthly Model'!M8*2.88,0) -> 72 | J7: =ROUND('Monthly Model'!Y8*2.88,0) -> 161
A8: Pro 订阅人数 | B8: =ROUND('Monthly Model'!G9*0.28,0) -> 0 | C8: =ROUND('Monthly Model'!M9*0.28,0) -> 4 | D8: =ROUND('Monthly Model'!Y9*0.28,0) -> 8 | E8: ='Monthly Model'!G9 -> 0 | F8: ='Monthly Model'!M9 -> 16 | G8: ='Monthly Model'!Y9 -> 29 | H8: =ROUND('Monthly Model'!G9*3.06,0) -> 0 | I8: =ROUND('Monthly Model'!M9*3.06,0) -> 49 | J8: =ROUND('Monthly Model'!Y9*3.06,0) -> 89
A9: 月度总收入 MRR ($) | B9: =ROUND('Monthly Model'!G16*0.55,0) -> 69 | C9: =ROUND('Monthly Model'!M16*0.55,0) -> 379 | D9: =ROUND('Monthly Model'!Y16*0.55,0) -> 2325 | E9: ='Monthly Model'!G16 -> 126 | F9: ='Monthly Model'!M16 -> 689 | G9: ='Monthly Model'!Y16 -> 4228 | H9: =ROUND('Monthly Model'!G16*1.8,0) -> 227 | I9: =ROUND('Monthly Model'!M16*1.8,0) -> 1240 | J9: =ROUND('Monthly Model'!Y16*1.8,0) -> 7610
A10: 月度运营成本 ($) | B10: =ROUND('Monthly Model'!G20*0.95,0) -> 142 | C10: =ROUND('Monthly Model'!M20*0.95,0) -> 151 | D10: =ROUND('Monthly Model'!Y20*0.95,0) -> 170 | E10: ='Monthly Model'!G20 -> 149.45 | F10: ='Monthly Model'!M20 -> 159.01 | G10: ='Monthly Model'!Y20 -> 179.03 | H10: =ROUND('Monthly Model'!G20*1.05,0) -> 157 | I10: =ROUND('Monthly Model'!M20*1.05,0) -> 167 | J10: =ROUND('Monthly Model'!Y20*1.05,0) -> 188
A11: 月度净利润 ($) | B11: =ROUND('Monthly Model'!G16*0.55-'Monthly Model'!G20*0.95,0) -> -73 | C11: =ROUND('Monthly Model'!M16*0.55-'Monthly Model'!M20*0.95,0) -> 228 | D11: =ROUND('Monthly Model'!Y16*0.55-'Monthly Model'!Y20*0.95,0) -> 2155 | E11: ='Monthly Model'!G22 -> -23.45 | F11: ='Monthly Model'!M22 -> 529.99 | G11: ='Monthly Model'!Y22 -> 4048.97 | H11: =ROUND('Monthly Model'!G16*1.8-'Monthly Model'!G20*1.05,0) -> 70 | I11: =ROUND('Monthly Model'!M16*1.8-'Monthly Model'!M20*1.05,0) -> 1073 | J11: =ROUND('Monthly Model'!Y16*1.8-'Monthly Model'!Y20*1.05,0) -> 7422
A14: 盈亏平衡分析 Break-even Analysis
A15: 运营盈亏平衡月份 (不含开发成本) | B15: ~M9 | E15: ~M7 | H15: ~M5
A16: 完全盈亏平衡月份 (含开发成本) | B16: ~M22 | E16: ~M14 | H16: ~M10
A17: Year 1 累计亏损 ($) | B17: $(15,000) | E17: $(8,500) | H17: $(3,200)
A18: Year 2 年化收入 ARR ($) | B18: $18,000-25,000 | E18: $45,000-60,000 | H18: $90,000-120,000

Sheet Charts
A1: WeeklyAI · 收益曲线图表
